Traceback (most recent call last):
  File "/usr/share/miniconda3/envs/networks/lib/python3.11/site-packages/jupyter_cache/executors/utils.py", line 58, in single_nb_execution
    executenb(
  File "/usr/share/miniconda3/envs/networks/lib/python3.11/site-packages/nbclient/client.py", line 1204, in execute
    return NotebookClient(nb=nb, resources=resources, km=km, **kwargs).execute()
           ^^^^^^^^^^^^^^^^^^^^^^^^^^^^^^^^^^^^^^^^^^^^^^^^^^^^^^^^^^^^^^^^^^^^^
  File "/usr/share/miniconda3/envs/networks/lib/python3.11/site-packages/nbclient/util.py", line 84, in wrapped
    return just_run(coro(*args, **kwargs))
           ^^^^^^^^^^^^^^^^^^^^^^^^^^^^^^^
  File "/usr/share/miniconda3/envs/networks/lib/python3.11/site-packages/nbclient/util.py", line 62, in just_run
    return loop.run_until_complete(coro)
           ^^^^^^^^^^^^^^^^^^^^^^^^^^^^^
  File "/usr/share/miniconda3/envs/networks/lib/python3.11/asyncio/base_events.py", line 653, in run_until_complete
    return future.result()
           ^^^^^^^^^^^^^^^
  File "/usr/share/miniconda3/envs/networks/lib/python3.11/site-packages/nbclient/client.py", line 663, in async_execute
    await self.async_execute_cell(
  File "/usr/share/miniconda3/envs/networks/lib/python3.11/site-packages/nbclient/client.py", line 965, in async_execute_cell
    await self._check_raise_for_error(cell, cell_index, exec_reply)
  File "/usr/share/miniconda3/envs/networks/lib/python3.11/site-packages/nbclient/client.py", line 862, in _check_raise_for_error
    raise CellExecutionError.from_cell_and_msg(cell, exec_reply_content)
nbclient.exceptions.CellExecutionError: An error occurred while executing the following cell:
------------------
import numpy as np                                            
import matplotlib.pyplot as plt       
import quantecon_book_networks                  
from mpl_toolkits.mplot3d.axes3d import Axes3D, proj3d  
from matplotlib import cm          
export_figures = False
quantecon_book_networks.config("matplotlib")                     
------------------

[0;31m---------------------------------------------------------------------------[0m
[0;31mModuleNotFoundError[0m                       Traceback (most recent call last)
Cell [0;32mIn[1], line 3[0m
[1;32m      1[0m [38;5;28;01mimport[39;00m [38;5;21;01mnumpy[39;00m [38;5;28;01mas[39;00m [38;5;21;01mnp[39;00m                                            
[1;32m      2[0m [38;5;28;01mimport[39;00m [38;5;21;01mmatplotlib[39;00m[38;5;21;01m.[39;00m[38;5;21;01mpyplot[39;00m [38;5;28;01mas[39;00m [38;5;21;01mplt[39;00m       
[0;32m----> 3[0m [38;5;28;01mimport[39;00m [38;5;21;01mquantecon_book_networks[39;00m                  
[1;32m      4[0m [38;5;28;01mfrom[39;00m [38;5;21;01mmpl_toolkits[39;00m[38;5;21;01m.[39;00m[38;5;21;01mmplot3d[39;00m[38;5;21;01m.[39;00m[38;5;21;01maxes3d[39;00m [38;5;28;01mimport[39;00m Axes3D, proj3d  
[1;32m      5[0m [38;5;28;01mfrom[39;00m [38;5;21;01mmatplotlib[39;00m [38;5;28;01mimport[39;00m cm          

[0;31mModuleNotFoundError[0m: No module named 'quantecon_book_networks'
ModuleNotFoundError: No module named 'quantecon_book_networks'

